Workbook

Sheet Hoja1
A1: Nombre
A2: =D2 -> NOMBRE: DAVID ANZOLEAGA MONTECINOS . . | D2: =IF('PEGAR DATOS AQUI'!$D2="","","NOMBRE: "&UPPER('PEGAR DATOS AQUI'!B2)&" "&'PEGAR DATOS AQUI'!C2&" "&'PEGAR DATOS AQUI'!D2) -> NOMBRE: DAVID ANZOLEAGA MONTECINOS . . | E2: =IF(D2="","","DIPLOMADO: "&UPPER('PEGAR DATOS AQUI'!$G$1)&"") -> DIPLOMADO: ETHICAL HACKING Y CIBERSEGURIDAD CON INTELIGENCIA ARTIFICIAL V7
A3: =E2 -> DIPLOMADO: ETHICAL HACKING Y CIBERSEGURIDAD CON INTELIGENCIA ARTIFICIAL V7 | D3: =IF('PEGAR DATOS AQUI'!$D3="","","NOMBRE: "&UPPER('PEGAR DATOS AQUI'!B3)&" "&'PEGAR DATOS AQUI'!C3&" "&'PEGAR DATOS AQUI'!D3) -> NOMBRE: EBERTH CANAVIRI . . | E3: =IF(D3="","","DIPLOMADO: "&UPPER('PEGAR DATOS AQUI'!$G$1)&"") -> DIPLOMADO: ETHICAL HACKING Y CIBERSEGURIDAD CON INTELIGENCIA ARTIFICIAL V7
A4: =D3 -> NOMBRE: EBERTH CANAVIRI . . | D4: =IF('PEGAR DATOS AQUI'!$D4="","","NOMBRE: "&UPPER('PEGAR DATOS AQUI'!B4)&" "&'PEGAR DATOS AQUI'!C4&" "&'PEGAR DATOS AQUI'!D4) -> NOMBRE: JUANITOPSF . . | E4: =IF(D4="","","DIPLOMADO: "&UPPER('PEGAR DATOS AQUI'!$G$1)&"") -> DIPLOMADO: ETHICAL HACKING Y CIBERSEGURIDAD CON INTELIGENCIA ARTIFICIAL V7
A5: =E3 -> DIPLOMADO: ETHICAL HACKING Y CIBERSEGURIDAD CON INTELIGENCIA ARTIFICIAL V7 | D5: =IF('PEGAR DATOS AQUI'!$D5="","","NOMBRE: "&UPPER('PEGAR DATOS AQUI'!B5)&" "&'PEGAR DATOS AQUI'!C5&" "&'PEGAR DATOS AQUI'!D5) -> NOMBRE: . . | E5: =IF(D5="","","DIPLOMADO: "&UPPER('PEGAR DATOS AQUI'!$G$1)&"") -> DIPLOMADO: ETHICAL HACKING Y CIBERSEGURIDAD CON INTELIGENCIA ARTIFICIAL V7
A6: =D4 -> NOMBRE: JUANITOPSF . . | D6: =IF('PEGAR DATOS AQUI'!$D6="","","NOMBRE: "&UPPER('PEGAR DATOS AQUI'!B6)&" "&'PEGAR DATOS AQUI'!C6&" "&'PEGAR DATOS AQUI'!D6) -> NOMBRE: . . | E6: =IF(D6="","","DIPLOMADO: "&UPPER('PEGAR DATOS AQUI'!$G$1)&"") -> DIPLOMADO: ETHICAL HACKING Y CIBERSEGURIDAD CON INTELIGENCIA ARTIFICIAL V7
A7: =E4 -> DIPLOMADO: ETHICAL HACKING Y CIBERSEGURIDAD CON INTELIGENCIA ARTIFICIAL V7 | D7: =IF('PEGAR DATOS AQUI'!$D7="","","NOMBRE: "&UPPER('PEGAR DATOS AQUI'!B7)&" "&'PEGAR DATOS AQUI'!C7&" "&'PEGAR DATOS AQUI'!D7) -> NOMBRE: . . | E7: =IF(D7="","","DIPLOMADO: "&UPPER('PEGAR DATOS AQUI'!$G$1)&"") -> DIPLOMADO: ETHICAL HACKING Y CIBERSEGURIDAD CON INTELIGENCIA ARTIFICIAL V7
A8: =D5 -> NOMBRE: . . | D8: =IF('PEGAR DATOS AQUI'!$D8="","","NOMBRE: "&UPPER('PEGAR DATOS AQUI'!B8)&" "&'PEGAR DATOS AQUI'!C8&" "&'PEGAR DATOS AQUI'!D8) -> NOMBRE: . . | E8: =IF(D8="","","DIPLOMADO: "&UPPER('PEGAR DATOS AQUI'!$G$1)&"") -> DIPLOMADO: ETHICAL HACKING Y CIBERSEGURIDAD CON INTELIGENCIA ARTIFICIAL V7
A9: =E5 -> DIPLOMADO: ETHICAL HACKING Y CIBERSEGURIDAD CON INTELIGENCIA ARTIFICIAL V7 | D9: =IF('PEGAR DATOS AQUI'!$D9="","","NOMBRE: "&UPPER('PEGAR DATOS AQUI'!B9)&" "&'PEGAR DATOS AQUI'!C9&" "&'PEGAR DATOS AQUI'!D9) -> NOMBRE: . . | E9: =IF(D9="","","DIPLOMADO: "&UPPER('PEGAR DATOS AQUI'!$G$1)&"") -> DIPLOMADO: ETHICAL HACKING Y CIBERSEGURIDAD CON INTELIGENCIA ARTIFICIAL V7
A10: =D6 -> NOMBRE: . . | D10: =IF('PEGAR DATOS AQUI'!$D10="","","NOMBRE: "&UPPER('PEGAR DATOS AQUI'!B10)&" "&'PEGAR DATOS AQUI'!C10&" "&'PEGAR DATOS AQUI'!D10) -> NOMBRE: . . | E10: =IF(D10="","","DIPLOMADO: "&UPPER('PEGAR DATOS AQUI'!$G$1)&"") -> DIPLOMADO: ETHICAL HACKING Y CIBERSEGURIDAD CON INTELIGENCIA ARTIFICIAL V7
A11: =E6 -> DIPLOMADO: ETHICAL HACKING Y CIBERSEGURIDAD CON INTELIGENCIA ARTIFICIAL V7 | D11: =IF('PEGAR DATOS AQUI'!$D11="","","NOMBRE: "&UPPER('PEGAR DATOS AQUI'!B11)&" "&'PEGAR DATOS AQUI'!C11&" "&'PEGAR DATOS AQUI'!D11) -> NOMBRE: . . | E11: =IF(D11="","","DIPLOMADO: "&UPPER('PEGAR DATOS AQUI'!$G$1)&"") -> DIPLOMADO: ETHICAL HACKING Y CIBERSEGURIDAD CON INTELIGENCIA ARTIFICIAL V7
A12: =D7 -> NOMBRE: . . | D12: =IF('PEGAR DATOS AQUI'!$D12="","","NOMBRE: "&UPPER('PEGAR DATOS AQUI'!B12)&" "&'PEGAR DATOS AQUI'!C12&" "&'PEGAR DATOS AQUI'!D12) -> NOMBRE: . . | E12: =IF(D12="","","DIPLOMADO: "&UPPER('PEGAR DATOS AQUI'!$G$1)&"") -> DIPLOMADO: ETHICAL HACKING Y CIBERSEGURIDAD CON INTELIGENCIA ARTIFICIAL V7
A13: =E7 -> DIPLOMADO: ETHICAL HACKING Y CIBERSEGURIDAD CON INTELIGENCIA ARTIFICIAL V7 | D13: =IF('PEGAR DATOS AQUI'!$D13="","","NOMBRE: "&UPPER('PEGAR DATOS AQUI'!B13)&" "&'PEGAR DATOS AQUI'!C13&" "&'PEGAR DATOS AQUI'!D13) -> NOMBRE: . . | E13: =IF(D13="","","DIPLOMADO: "&UPPER('PEGAR DATOS AQUI'!$G$1)&"") -> DIPLOMADO: ETHICAL HACKING Y CIBERSEGURIDAD CON INTELIGENCIA ARTIFICIAL V7
A14: =D8 -> NOMBRE: . . | D14: =IF('PEGAR DATOS AQUI'!$D14="","","NOMBRE: "&UPPER('PEGAR DATOS AQUI'!B14)&" "&'PEGAR DATOS AQUI'!C14&" "&'PEGAR DATOS AQUI'!D14) -> NOMBRE: . . | E14: =IF(D14="","","DIPLOMADO: "&UPPER('PEGAR DATOS AQUI'!$G$1)&"") -> DIPLOMADO: ETHICAL HACKING Y CIBERSEGURIDAD CON INTELIGENCIA ARTIFICIAL V7
A15: =E8 -> DIPLOMADO: ETHICAL HACKING Y CIBERSEGURIDAD CON INTELIGENCIA ARTIFICIAL V7 | D15: =IF('PEGAR DATOS AQUI'!$D15="","","NOMBRE: "&UPPER('PEGAR DATOS AQUI'!B15)&" "&'PEGAR DATOS AQUI'!C15&" "&'PEGAR DATOS AQUI'!D15) -> NOMBRE: . . | E15: =IF(D15="","","DIPLOMADO: "&UPPER('PEGAR DATOS AQUI'!$G$1)&"") -> DIPLOMADO: ETHICAL HACKING Y CIBERSEGURIDAD CON INTELIGENCIA ARTIFICIAL V7
A16: =D9 -> NOMBRE: . . | D16: =IF('PEGAR DATOS AQUI'!$D16="","","NOMBRE: "&UPPER('PEGAR DATOS AQUI'!B16)&" "&'PEGAR DATOS AQUI'!C16&" "&'PEGAR DATOS AQUI'!D16) -> NOMBRE: . . | E16: =IF(D16="","","DIPLOMADO: "&UPPER('PEGAR DATOS AQUI'!$G$1)&"") -> DIPLOMADO: ETHICAL HACKING Y CIBERSEGURIDAD CON INTELIGENCIA ARTIFICIAL V7
A17: =E9 -> DIPLOMADO: ETHICAL HACKING Y CIBERSEGURIDAD CON INTELIGENCIA ARTIFICIAL V7 | D17: =IF('PEGAR DATOS AQUI'!$D17="","","NOMBRE: "&UPPER('PEGAR DATOS AQUI'!B17)&" "&'PEGAR DATOS AQUI'!C17&" "&'PEGAR DATOS AQUI'!D17) -> NOMBRE: . . | E17: =IF(D17="","","DIPLOMADO: "&UPPER('PEGAR DATOS AQUI'!$G$1)&"") -> DIPLOMADO: ETHICAL HACKING Y CIBERSEGURIDAD CON INTELIGENCIA ARTIFICIAL V7
A18: =D10 -> NOMBRE: . . | D18: =IF('PEGAR DATOS AQUI'!$D18="","","NOMBRE: "&UPPER('PEGAR DATOS AQUI'!B18)&" "&'PEGAR DATOS AQUI'!C18&" "&'PEGAR DATOS AQUI'!D18) -> NOMBRE: . . | E18: =IF(D18="","","DIPLOMADO: "&UPPER('PEGAR DATOS AQUI'!$G$1)&"") -> DIPLOMADO: ETHICAL HACKING Y CIBERSEGURIDAD CON INTELIGENCIA ARTIFICIAL V7
A19: =E10 -> DIPLOMADO: ETHICAL HACKING Y CIBERSEGURIDAD CON INTELIGENCIA ARTIFICIAL V7 | D19: =IF('PEGAR DATOS AQUI'!$D19="","","NOMBRE: "&UPPER('PEGAR DATOS AQUI'!B19)&" "&'PEGAR DATOS AQUI'!C19&" "&'PEGAR DATOS AQUI'!D19) -> NOMBRE: . . | E19: =IF(D19="","","DIPLOMADO: "&UPPER('PEGAR DATOS AQUI'!$G$1)&"") -> DIPLOMADO: ETHICAL HACKING Y CIBERSEGURIDAD CON INTELIGENCIA ARTIFICIAL V7
A20: =D11 -> NOMBRE: . . | D20: =IF('PEGAR DATOS AQUI'!$D20="","","NOMBRE: "&UPPER('PEGAR DATOS AQUI'!B20)&" "&'PEGAR DATOS AQUI'!C20&" "&'PEGAR DATOS AQUI'!D20) -> NOMBRE: . . | E20: =IF(D20="","","DIPLOMADO: "&UPPER('PEGAR DATOS AQUI'!$G$1)&"") -> DIPLOMADO: ETHICAL HACKING Y CIBERSEGURIDAD CON INTELIGENCIA ARTIFICIAL V7
A21: =E11 -> DIPLOMADO: ETHICAL HACKING Y CIBERSEGURIDAD CON INTELIGENCIA ARTIFICIAL V7 | D21: =IF('PEGAR DATOS AQUI'!$D21="","","NOMBRE: "&UPPER('PEGAR DATOS AQUI'!B21)&" "&'PEGAR DATOS AQUI'!C21&" "&'PEGAR DATOS AQUI'!D21) -> NOMBRE: . . | E21: =IF(D21="","","DIPLOMADO: "&UPPER('PEGAR DATOS AQUI'!$G$1)&"") -> DIPLOMADO: ETHICAL HACKING Y CIBERSEGURIDAD CON INTELIGENCIA ARTIFICIAL V7
A22: =D12 -> NOMBRE: . . | D22: =IF('PEGAR DATOS AQUI'!$D22="","","NOMBRE: "&UPPER('PEGAR DATOS AQUI'!B22)&" "&'PEGAR DATOS AQUI'!C22&" "&'PEGAR DATOS AQUI'!D22) -> NOMBRE: . . | E22: =IF(D22="","","DIPLOMADO: "&UPPER('PEGAR DATOS AQUI'!$G$1)&"") -> DIPLOMADO: ETHICAL HACKING Y CIBERSEGURIDAD CON INTELIGENCIA ARTIFICIAL V7
A23: =E12 -> DIPLOMADO: ETHICAL HACKING Y CIBERSEGURIDAD CON INTELIGENCIA ARTIFICIAL V7 | D23: =IF('PEGAR DATOS AQUI'!$D23="","","NOMBRE: "&UPPER('PEGAR DATOS AQUI'!B23)&" "&'PEGAR DATOS AQUI'!C23&" "&'PEGAR DATOS AQUI'!D23) -> NOMBRE: . . | E23: =IF(D23="","","DIPLOMADO: "&UPPER('PEGAR DATOS AQUI'!$G$1)&"") -> DIPLOMADO: ETHICAL HACKING Y CIBERSEGURIDAD CON INTELIGENCIA ARTIFICIAL V7
A24: =D13 -> NOMBRE: . . | D24: =IF('PEGAR DATOS AQUI'!$D24="","","NOMBRE: "&UPPER('PEGAR DATOS AQUI'!B24)&" "&'PEGAR DATOS AQUI'!C24&" "&'PEGAR DATOS AQUI'!D24) -> NOMBRE: . . | E24: =IF(D24="","","DIPLOMADO: "&UPPER('PEGAR DATOS AQUI'!$G$1)&"") -> DIPLOMADO: ETHICAL HACKING Y CIBERSEGURIDAD CON INTELIGENCIA ARTIFICIAL V7
A25: =E13 -> DIPLOMADO: ETHICAL HACKING Y CIBERSEGURIDAD CON INTELIGENCIA ARTIFICIAL V7 | D25: =IF('PEGAR DATOS AQUI'!$D25="","","NOMBRE: "&UPPER('PEGAR DATOS AQUI'!B25)&" "&'PEGAR DATOS AQUI'!C25&" "&'PEGAR DATOS AQUI'!D25) -> NOMBRE: . . | E25: =IF(D25="","","DIPLOMADO: "&UPPER('PEGAR DATOS AQUI'!$G$1)&"") -> DIPLOMADO: ETHICAL HACKING Y CIBERSEGURIDAD CON INTELIGENCIA ARTIFICIAL V7
A26: =D14 -> NOMBRE: . . | D26: =IF('PEGAR DATOS AQUI'!$D26="","","NOMBRE: "&UPPER('PEGAR DATOS AQUI'!B26)&" "&'PEGAR DATOS AQUI'!C26&" "&'PEGAR DATOS AQUI'!D26) -> NOMBRE: . . | E26: =IF(D26="","","DIPLOMADO: "&UPPER('PEGAR DATOS AQUI'!$G$1)&"") -> DIPLOMADO: ETHICAL HACKING Y CIBERSEGURIDAD CON INTELIGENCIA ARTIFICIAL V7
A27: =E14 -> DIPLOMADO: ETHICAL HACKING Y CIBERSEGURIDAD CON INTELIGENCIA ARTIFICIAL V7 | D27: =IF('PEGAR DATOS AQUI'!$D27="","","NOMBRE: "&UPPER('PEGAR DATOS AQUI'!B27)&" "&'PEGAR DATOS AQUI'!C27&" "&'PEGAR DATOS AQUI'!D27) -> NOMBRE: . . | E27: =IF(D27="","","DIPLOMADO: "&UPPER('PEGAR DATOS AQUI'!$G$1)&"") -> DIPLOMADO: ETHICAL HACKING Y CIBERSEGURIDAD CON INTELIGENCIA ARTIFICIAL V7
A28: =D15 -> NOMBRE: . . | D28: =IF('PEGAR DATOS AQUI'!$D28="","","NOMBRE: "&UPPER('PEGAR DATOS AQUI'!B28)&" "&'PEGAR DATOS AQUI'!C28&" "&'PEGAR DATOS AQUI'!D28) -> NOMBRE: . . | E28: =IF(D28="","","DIPLOMADO: "&UPPER('PEGAR DATOS AQUI'!$G$1)&"") -> DIPLOMADO: ETHICAL HACKING Y CIBERSEGURIDAD CON INTELIGENCIA ARTIFICIAL V7
A29: =E15 -> DIPLOMADO: ETHICAL HACKING Y CIBERSEGURIDAD CON INTELIGENCIA ARTIFICIAL V7 | D29: =IF('PEGAR DATOS AQUI'!$D29="","","NOMBRE: "&UPPER('PEGAR DATOS AQUI'!B29)&" "&'PEGAR DATOS AQUI'!C29&" "&'PEGAR DATOS AQUI'!D29) -> NOMBRE: . . | E29: =IF(D29="","","DIPLOMADO: "&UPPER('PEGAR DATOS AQUI'!$G$1)&"") -> DIPLOMADO: ETHICAL HACKING Y CIBERSEGURIDAD CON INTELIGENCIA ARTIFICIAL V7
A30: =D16 -> NOMBRE: . . | D30: =IF('PEGAR DATOS AQUI'!$D30="","","NOMBRE: "&UPPER('PEGAR DATOS AQUI'!B30)&" "&'PEGAR DATOS AQUI'!C30&" "&'PEGAR DATOS AQUI'!D30) -> NOMBRE: . . | E30: =IF(D30="","","DIPLOMADO: "&UPPER('PEGAR DATOS AQUI'!$G$1)&"") -> DIPLOMADO: ETHICAL HACKING Y CIBERSEGURIDAD CON INTELIGENCIA ARTIFICIAL V7
A31: =E16 -> DIPLOMADO: ETHICAL HACKING Y CIBERSEGURIDAD CON INTELIGENCIA ARTIFICIAL V7 | D31: =IF('PEGAR DATOS AQUI'!$D31="","","NOMBRE: "&UPPER('PEGAR DATOS AQUI'!B31)&" "&'PEGAR DATOS AQUI'!C31&" "&'PEGAR DATOS AQUI'!D31) -> NOMBRE: . . | E31: =IF(D31="","","DIPLOMADO: "&UPPER('PEGAR DATOS AQUI'!$G$1)&"") -> DIPLOMADO: ETHICAL HACKING Y CIBERSEGURIDAD CON INTELIGENCIA ARTIFICIAL V7
A32: =D17 -> NOMBRE: . . | D32: =IF('PEGAR DATOS AQUI'!$D32="","","NOMBRE: "&UPPER('PEGAR DATOS AQUI'!B32)&" "&'PEGAR DATOS AQUI'!C32&" "&'PEGAR DATOS AQUI'!D32) -> NOMBRE: . . | E32: =IF(D32="","","DIPLOMADO: "&UPPER('PEGAR DATOS AQUI'!$G$1)&"") -> DIPLOMADO: ETHICAL HACKING Y CIBERSEGURIDAD CON INTELIGENCIA ARTIFICIAL V7
A33: =E17 -> DIPLOMADO: ETHICAL HACKING Y CIBERSEGURIDAD CON INTELIGENCIA ARTIFICIAL V7 | D33: =IF('PEGAR DATOS AQUI'!$D33="","","NOMBRE: "&UPPER('PEGAR DATOS AQUI'!B33)&" "&'PEGAR DATOS AQUI'!C33&" "&'PEGAR DATOS AQUI'!D33) -> NOMBRE: . . | E33: =IF(D33="","","DIPLOMADO: "&UPPER('PEGAR DATOS AQUI'!$G$1)&"") -> DIPLOMADO: ETHICAL HACKING Y CIBERSEGURIDAD CON INTELIGENCIA ARTIFICIAL V7
A34: =D18 -> NOMBRE: . . | D34: =IF('PEGAR DATOS AQUI'!$D34="","","NOMBRE: "&UPPER('PEGAR DATOS AQUI'!B34)&" "&'PEGAR DATOS AQUI'!C34&" "&'PEGAR DATOS AQUI'!D34) | E34: =IF(D34="","","DIPLOMADO: "&UPPER('PEGAR DATOS AQUI'!$G$1)&"")
A35: =E18 -> DIPLOMADO: ETHICAL HACKING Y CIBERSEGURIDAD CON INTELIGENCIA ARTIFICIAL V7 | D35: =IF('PEGAR DATOS AQUI'!$D35="","","NOMBRE: "&UPPER('PEGAR DATOS AQUI'!B35)&" "&'PEGAR DATOS AQUI'!C35&" "&'PEGAR DATOS AQUI'!D35) | E35: =IF(D35="","","DIPLOMADO: "&UPPER('PEGAR DATOS AQUI'!$G$1)&"")
A36: =D19 -> NOMBRE: . . | D36: =IF('PEGAR DATOS AQUI'!$D36="","","NOMBRE: "&UPPER('PEGAR DATOS AQUI'!B36)&" "&'PEGAR DATOS AQUI'!C36&" "&'PEGAR DATOS AQUI'!D36) | E36: =IF(D36="","","DIPLOMADO: "&UPPER('PEGAR DATOS AQUI'!$G$1)&"")
A37: =E19 -> DIPLOMADO: ETHICAL HACKING Y CIBERSEGURIDAD CON INTELIGENCIA ARTIFICIAL V7 | D37: =IF('PEGAR DATOS AQUI'!$D37="","","NOMBRE: "&UPPER('PEGAR DATOS AQUI'!B37)&" "&'PEGAR DATOS AQUI'!C37&" "&'PEGAR DATOS AQUI'!D37) | E37: =IF(D37="","","DIPLOMADO: "&UPPER('PEGAR DATOS AQUI'!$G$1)&"")
A38: =D20 -> NOMBRE: . . | D38: =IF('PEGAR DATOS AQUI'!$D38="","","NOMBRE: "&UPPER('PEGAR DATOS AQUI'!B38)&" "&'PEGAR DATOS AQUI'!C38&" "&'PEGAR DATOS AQUI'!D38) | E38: =IF(D38="","","DIPLOMADO: "&UPPER('PEGAR DATOS AQUI'!$G$1)&"")
A39: =E20 -> DIPLOMADO: ETHICAL HACKING Y CIBERSEGURIDAD CON INTELIGENCIA ARTIFICIAL V7 | D39: =IF('PEGAR DATOS AQUI'!$D39="","","NOMBRE: "&UPPER('PEGAR DATOS AQUI'!B39)&" "&'PEGAR DATOS AQUI'!C39&" "&'PEGAR DATOS AQUI'!D39) | E39: =IF(D39="","","DIPLOMADO: "&UPPER('PEGAR DATOS AQUI'!$G$1)&"")
A40: =D21 -> NOMBRE: . . | D40: =IF('PEGAR DATOS AQUI'!$D40="","","NOMBRE: "&UPPER('PEGAR DATOS AQUI'!B40)&" "&'PEGAR DATOS AQUI'!C40&" "&'PEGAR DATOS AQUI'!D40) | E40: =IF(D40="","","DIPLOMADO: "&UPPER('PEGAR DATOS AQUI'!$G$1)&"")
...

Sheet PEGAR DATOS AQUI
A1: Nº | B1: Apellido Paterno | C1: Apellido Materno | D1: Nombres | F1: DIPLOMADO: | G1: ETHICAL HACKING Y CIBERSEGURIDAD CON INTELIGENCIA ARTIFICIAL V7
A2: 1 | B2: DAVID ANZOLEAGA MONTECINOS | C2: . | D2: . | F2: SUBTITULO:
A3: 2 | B3: EBERTH CANAVIRI | C3: . | D3: . | F3: SUBTITULO:
A4: 3 | B4: juanitopsf | C4: . | D4: . | F4: SUBTITULO:
A5: 4 | C5: . | D5: . | F5: SUBTITULO:
A6: 5 | C6: . | D6: . | F6: SUBTITULO:
A7: 6 | C7: . | D7: . | F7: SUBTITULO:
A8: 7 | C8: . | D8: . | F8: SUBTITULO:
A9: 8 | C9: . | D9: .
A10: 9 | C10: . | D10: .
A11: 10 | C11: . | D11: .
A12: 11 | C12: . | D12: .
A13: 12 | C13: . | D13: .
A14: 13 | C14: . | D14: .
A15: 14 | C15: . | D15: .
A16: 15 | C16: . | D16: .
A17: 16 | C17: . | D17: .
A18: 17 | C18: . | D18: .
A19: 18 | C19: . | D19: .
A20: 19 | C20: . | D20: .
... A33: 32 | C33: . | D33: .
A34: 33

Sheet Hoja2
A1: https://drive.google.com/file/d/1LHvR2olID1VPH4n06CJOO5ZYqXjmjCbY/view?usp=sharing | B1: APELLIDO MATERNO | C1: PRIMER NOMBRE | D1: SEGUNDO NOMBRE | E1: CI | F1: GRADO ACADEMICO | G1: MÓDULO 1 | H1: MÓDULO 2 | I1: MÓDULO 3 | J1: MÓDULO 4
A2: AGUILAR | B2: AYMA | C2: EDWIN | E2: 3532870 | F2: TITULADO | G2: 98 | H2: 61 | I2: 62 | J2: 79 | M2: =C2&" "&D2 -> EDWIN
A3: AGUILAR | B3: AYMA | C3: GONZALO | E3: 3553876 | F3: TITULADO | G3: 87 | H3: 67 | I3: 70 | J3: 77 | M3: =C3&" "&D3 -> GONZALO
A4: APAZA | B4: RODRIGUEZ | C4: EDGAR | E4: 6684088 | F4: TITULADO | G4: 97 | H4: 72 | I4: 65 | J4: 87 | M4: =C4&" "&D4 -> EDGAR
A5: AREBALO | B5: NINA | C5: IVER | E5: 8696343 | F5: TITULADO | G5: 87 | H5: 74 | I5: 70 | J5: 82 | M5: =C5&" "&D5 -> IVER
A6: AYLLON | B6: CAZON | C6: LUIS FERNANDO | D6: FERNANDO | E6: 7189868 | F6: TITULADO | G6: 97 | H6: 52 | I6: 62 | J6: 61 | M6: =C6&" "&D6 -> LUIS FERNANDO FERNANDO
A7: BERMUDEZ | B7: GUTIERREZ | C7: OSCAR ENRIQUE | D7: ENRIQUE | E7: 12936839 | F7: TITULADO | G7: 92 | H7: 32 | I7: 67 | J7: 86 | M7: =C7&" "&D7 -> OSCAR ENRIQUE ENRIQUE
A8: CACHACA | B8: POMA | C8: JULIO CESAR | D8: CESAR | E8: 9070418 | F8: TITULADO | G8: 97 | H8: 75 | I8: 70 | J8: 86 | M8: =C8&" "&D8 -> JULIO CESAR CESAR
A9: GOMEZ | B9: CHOQUE | C9: RONALD CESAR | D9: CESAR | E9: 5741597 | F9: TITULADO | G9: 96 | H9: 61 | I9: 61 | J9: 88 | M9: =C9&" "&D9 -> RONALD CESAR CESAR
A10: HERBAS | B10: MONTAÑO | C10: JOEL RONAL | D10: RONAL | E10: 7934507 | F10: TITULADO | G10: 93 | H10: 77 | I10: 65 | J10: 82 | M10: =C10&" "&D10 -> JOEL RONAL RONAL
A11: HILAQUITA | B11: YUJRA | C11: LILIAN RUZENA | D11: RUZENA | E11: 9332721 | F11: TITULADO | G11: 89 | H11: 75 | I11: 61 | J11: 89 | M11: =C11&" "&D11 -> LILIAN RUZENA RUZENA
A12: HINOJOSA | B12: CAMACHO | C12: KEVIN ALEXANDER | D12: ALEXANDER | E12: 7910004 | F12: TITULADO | G12: 94 | H12: 61 | I12: 65 | J12: 87 | M12: =C12&" "&D12 -> KEVIN ALEXANDER ALEXANDER
A13: HUAYTA | B13: RAMOS | C13: SANTOS RICHARD | D13: RICHARD | E13: 6708682 | F13: TITULADO | G13: 98 | H13: 67 | I13: 72 | J13: 95 | M13: =C13&" "&D13 -> SANTOS RICHARD RICHARD
A14: LLANOS | B14: FLORES | C14: UZIEL | E14: 6662001 | F14: EGRESADO | G14: 94 | H14: 61 | I14: 61 | J14: 68 | M14: =C14&" "&D14 -> UZIEL
A15: MACIAS | B15: PACHECO | C15: KEVIN | E15: 8342946 | F15: TITULADO | G15: 96 | H15: 61 | I15: 62 | J15: 98 | M15: =C15&" "&D15 -> KEVIN
A16: MAITA | B16: NICASIO | C16: ABDON | E16: 5546751-1V | F16: EGRESADO | G16: 87 | H16: 40 | I16: 61 | J16: 61 | M16: =C16&" "&D16 -> ABDON
A17: MAMANI | B17: AGUILAR | C17: EDSON DERIK | D17: DERIK | E17: 7044386 | F17: TITULADO | G17: 99 | H17: 71 | I17: 70 | J17: 82 | M17: =C17&" "&D17 -> EDSON DERIK DERIK
A18: MAMANI | B18: PAUCARA | C18: HUGO ISRAEL | D18: ISRAEL | E18: 4305779 | F18: TITULADO | G18: 99 | H18: 72 | I18: 65 | J18: 93 | M18: =C18&" "&D18 -> HUGO ISRAEL ISRAEL
A19: MARISCAL | B19: MAMANI | C19: JAIRZINHO | E19: 4757154 | F19: TITULADO | G19: 98 | H19: 70 | I19: 0 | J19: 0 | M19: =C19&" "&D19 -> JAIRZINHO
A20: MELGAR | B20: APURI | C20: IVAN BLADIMIR | D20: BLADIMIR | E20: 6533057 | F20: TITULADO | G20: 95 | H20: 73 | I20: 61 | J20: 95 | M20: =C20&" "&D20 -> IVAN BLADIMIR BLADIMIR
A21: MERCADO | B21: CESPEDES | C21: JUAN DARIO | D21: DARIO | E21: 11362017 | F21: TITULADO | G21: 96 | H21: 64 | I21: 62 | J21: 80 | M21: =C21&" "&D21 -> JUAN DARIO DARIO
A22: MONTERO | B22: MEDRANO | C22: DAVID | E22: 9422644 | F22: TITULADO | G22: 97 | H22: 69 | I22: 68 | J22: 85 | M22: =C22&" "&D22 -> DAVID
A23: PACAJA | B23: CRUZ | C23: JUAN CARLOS | D23: CARLOS | E23: 7563109 | F23: TITULADO | G23: 95 | H23: 61 | I23: 61 | J23: 61 | M23: =C23&" "&D23 -> JUAN CARLOS CARLOS
A24: QUISPE | B24: CONDORI | C24: GROBER MARTIN | D24: MARTIN | E24: 6813976 | F24: TITULADO | G24: 94 | H24: 61 | I24: 68 | J24: 70 | M24: =C24&" "&D24 -> GROBER MARTIN MARTIN
A25: RAMOS | B25: CHIRINOS | C25: BRYAN ANGEL | D25: ANGEL | E25: 9222053 | F25: TITULADO | G25: 93 | H25: 76 | I25: 62 | J25: 92 | M25: =C25&" "&D25 -> BRYAN ANGEL ANGEL
A26: RIVAS | B26: BARRIENTOS | C26: FABIAM ROLANDO | D26: ROLANDO | E26: 4880443 | F26: TITULADO | G26: 96 | H26: 64 | I26: 65 | J26: 74 | M26: =C26&" "&D26 -> FABIAM ROLANDO ROLANDO
A27: URIBE | B27: PORTAL | C27: NOEMI VANESSA | D27: VANESSA | E27: 7378311 | F27: TITULADO | G27: 98 | H27: 61 | I27: 61 | J27: 6 | M27: =C27&" "&D27 -> NOEMI VANESSA VANESSA
A28: VEIZAGA | B28: GUTIERREZ | C28: FERNANDO NICOLAS | D28: NICOLAS | E28: 5724294 | F28: TITULADO | G28: 93 | H28: 67 | I28: 66 | J28: 90 | M28: =C28&" "&D28 -> FERNANDO NICOLAS NICOLAS
A29: VELASQUEZ | B29: CHOQUE | C29: LUZ TAMARA | D29: TAMARA | E29: 7211962 | F29: TITULADO | G29: 95 | H29: 82 | I29: 61 | J29: 62 | M29: =C29&" "&D29 -> LUZ TAMARA TAMARA
A30: VILLARROEL | B30: ZERNA | C30: ARACELY | E30: 6271909 | M30: =C30&" "&D30 -> ARACELY
A31: ZUÑIGA | B31: VELASQUEZ | C31: JAIRO ANDRES | D31: ANDRES | E31: 8234164 | M31: =C31&" "&D31 -> JAIRO ANDRES ANDRES
